Workbook

Sheet DataBase
A1: Customer ID | B1: Name | C1: Phone | D1: WhatsApp | E1: Area | F1: Address | G1: Location | H1: CreatedAt | I1: UpdatedAt | J1: IsActive | K1: Notes | L1: Round | M1: Round Status
M2: Inactive | N2: Inactive | O2: Active
A3: C1768653088625 | B3: Jasmine Behery | C3: 0529157624 | D3: 0529157624 | E3: Al danah | F3: شارع الكترا نفس بناية مطعم الابراهيمي شقة ٥٠٣ | G3: https://www.google.com/maps?q=24.488376387234172,54.36703744083892 | H3: 46039.647 | I3: 46160.602 | J3: TRUE
A4: C1768653219814 | B4: Hana | C4: 0523410536 | D4: 0523410536 | E4: ابو ظبي جزيرة الريم | F4: ابوظبي جزيرة الريم sea side tower 1206 | G4: https://www.google.com/maps?q=24.511217337965643,54.40646767616272 | H4: 46039.648 | I4: 46131.497 | J4: TRUE
A5: C1768655293606 | B5: Naglaa Eslam | C5: 0555060297 | D5: 0555060297 | E5: خليفه أ | F5: ٩١ شارع الكهرمان خليفه خلف الفرسان مول | G5: https://www.google.com/maps?q=24.396056135766734,54.5660779698686 | H5: 46039.672 | I5: 46162.754 | J5: TRUE
A6: C1768658567561 | B6: ريهام احمد | C6: 0525336427 | D6: 0525336427 | E6: شارع الدفاع | F6: شارع الدفاع بجوار مستشفي برجيل بناية٤٤ شقة ٣٠٤ | G6: https://www.google.com/maps?q=24.48040447704474,54.38423241719683 | H6: 46039.71 | I6: 46155.581 | J6: TRUE
A7: C1768659646212 | B7: فاطمة جودة | C7: 0509795823 | D7: 0509795823 | E7: بني ياس | F7: شارع الحضرة فيلا ٧ | G7: https://www.google.com/maps?q=24.298819,54.6298218 | H7: 46039.723 | I7: 46154.662 | J7: TRUE | N7: Verified | O7: 24.298819 | P7: 54.629822 | Q7: https://www.google.com/maps?q=24.298819,54.6298218
A8: C1768662454832 | B8: نرفانا محمد عاطف | C8: 0569389602 | D8: 0565627871 | E8: شخبوط | F8: شخبوط شارع الجوهر فيلا رقم ٤٥٧ شقة رقم ٣ | G8: https://www.google.com/maps?q=24.3810557,54.6477616 | H8: 46039.755 | I8: 46039.81 | J8: TRUE
A9: C1768662888362 | B9: Aya yasser abdullah | C9: 0552947780 | D9: 0552947780 | E9: شخبوط | F9: 44 Al lidama st / shakhbout | G9: https://www.google.com/maps?q=24.382185,54.6476835 | H9: 46039.76 | I9: 46095.889 | J9: TRUE
A10: C1768662948033 | B10: علي الجالي | C10: 0505837318 | D10: 0505837318 | E10: الكورنيش | F10: ابوظبي منطقة الدانه الكورنيش خلف Fabبنك نفس بناية الرصاصي للعطور وبقالة الورقاء بناية رقم 22 الطابق16شقة 164 | G10: https://www.google.com/maps?q=24.4904815,54.3553056 | H10: 46039.761 | I10: 46151.631 | J10: TRUE
A11: C1768667938927 | B11: عبد الرحمن السيد | C11: 0503553750 | D11: 0542170740 | E11: الدانه | F11: ش الكترا عماره اطلس للسياحه أمام فندق كوبثورن الدور التاسع شقه ٤٠٩ | G11: https://www.google.com/maps?q=24.4886349,54.367739 | H11: 46039.819 | I11: 46158.669 | J11: TRUE
A12: C1768674193071 | B12: سمر وفيق محمد | C12: 0585990297 | D12: 0585990297 | E12: جزيره الريم | F12: جزيره الريم هورايزون تاور E2/1801 | G12: https://www.google.com/maps?q=24.49400590864592,54.40334300908227 | H12: 46039.891 | I12: 46160.54 | J12: TRUE
A13: C1768675057347 | B13: Adam mohamed | C13: 0565572507 | D13: 0565572507 | E13: خليفه ا | F13: ابو ظبي خليفه ا | G13: https://www.google.com/maps?q=24.4059824,54.5766658 | H13: 46039.901 | I13: 46154.333 | J13: TRUE
A14: C1768679601145 | B14: Rania | C14: 0554132107 | D14: 0554132107 | E14: الخالديه | F14: شارع الكترا بناية العديل 1504 | G14: https://www.google.com/maps?q=24.475874096409036,54.35152796896546 | H14: 46039.954 | I14: 46145.391 | J14: TRUE
A15: C1768681153002 | B15: مريم رشدى | C15: 0503049782 | D15: 0503049782 | E15: الروضه | F15: ش الغريفة بناية C83 استديو 217 | G15: https://www.google.com/maps?q=24.420550506051583,54.46312538079711 | H15: 46039.972 | I15: 46155.891 | J15: TRUE | N15: Verified | O15: 24.420551 | P15: 54.463125 | Q15: https://www.google.com/maps?q=24.420550506051583,54.46312538079711
A16: C1768686351531 | B16: دعاء صالح | C16: 0503844380 | D16: 0503844380 | E16: شارع النجده | F16: شارع للنجده | G16: https://www.google.com/maps?q=24.4839715,54.3737652 | H16: 46040.032 | I16: 46144.599 | J16: TRUE
A17: C1768688109796 | B17: نورا هيكل | C17: 0502057406 | D17: 0502057406 | E17: الخالديه | F17: الخالديه.خلف مصرف عجمان.شارع اهل المجد.بنايه ٢٧.نفس بنايه فلانتين فلاور للزهور .شقه ٢٠٤ | G17: https://www.google.com/maps?q=24.4709703,54.348119 | H17: 46040.052 | I17: 46160.635 | J17: TRUE
A18: C1768692183021 | B18: معاذ | C18: 0506449502 | D18: 0506449502 | E18: بني ياس شرق 11 | F18: فيلا 287 بجانب فيلا 16. شارع المديفي بني ياس شرق 11 ابوظبي | G18: https://www.google.com/maps?q=24.30272614252692,54.665250525619385 | H18: 46040.099 | I18: 46124.957 | J18: TRUE
A19: C1768720835093 | B19: Shimaa Rubishy | C19: 0522248847 | D19: 0522248847 | E19: Reem island | F19: Marina square, building 5,2804 | G19: https://www.google.com/maps?q=24.491903455104953,54.3945336341858 | H19: 46040.431 | I19: 46145.662 | J19: TRUE
A20: C1768724038057 | B20: Amr Gamal | C20: 0561628421 | D20: 0561628421 | E20: Rabdan | F20: Abu Dhabi-Rabdan-25Ash shabaqi st | G20: https://www.google.com/maps?q=24.39945190748372,54.51725059485866 | H20: 46040.468 | I20: 46040.473 | J20: TRUE
A21: C1768734061541 | B21: Nourhan Tharwat | C21: 0543380860 | D21: 0543380860 | E21: الزاهيه | F21: شارع المينا بنايه النعيمي رقم 1 نفس بنايه صيدليه الافضل وبقاله أبو محمود الطابق العاشر شقه رقم 1003 | G21: https://www.google.com/maps?q=24.501827903456647,54.37353646634361 | H21: 46040.584 | I21: 46146.735 | J21: TRUE
A22: C1768735666922 | B22: Shima | C22: 0558106715 | D22: 0558106715 | E22: الخالديه | F22: 43 شارع زايد الاول مبني سيتي ون موبيل شوب بجوار km شقه 201 | G22: https://www.google.com/maps?q=24.474705582824225,54.35060262680053 | H22: 46040.603 | I22: 46160.712 | J22: TRUE
A23: C1768736034463 | B23: RIHAM FAYED | C23: 0561429142 | D23: 0561429142 | E23: الشامخه ايوظبي | F23: الشامخة ١٧ شارع الزناد ملحق فيلا ٢٠ شفه ١ | G23: https://www.google.com/maps?q=24.3776618,54.7038044 | H23: 46040.607 | I23: 46151.61 | J23: TRUE
A24: C1768741994250 | B24: اسماء عيد | C24: 0544990406 | D24: 0544990406 | E24: بني ياس غرب 2 | F24: Baniyas West 2, 502, Building 262 | G24: https://www.google.com/maps?q=24.2942413364381,54.625878274418945 | H24: 46040.676 | I24: 46060.088 | J24: TRUE
A25: C1768749793555 | B25: هند المنشاوي | C25: 0559730049 | D25: 0559730049 | E25: بني ياس شرق ١ | F25: فيلا 88 الغابات القديمة بني ياس شارع المويجعي | G25: https://www.google.com/maps?q=24.31961788714769,54.615672826003 | H25: 46040.766 | I25: 46151.562 | J25: TRUE
A26: C1768753558875 | B26: Asmaa Ismail | C26: 0507454979 | D26: 0507454979 | E26: الشامخه | F26: الشامخه نفس اللوكيشن البنايه الخضراء | G26: https://www.google.com/maps?q=24.3869237,54.7153942 | H26: 46040.81 | I26: 46124.653 | J26: TRUE
A27: C1768753659322 | B27: محمد احمد | C27: 0528005162 | D27: 0559104514 | E27: المناصير | F27: المناصير شارع الفكر بناية ١٣ | G27: https://www.google.com/maps?q=24.4604924,54.3607518 | H27: 46040.811 | I27: 46158.965 | J27: TRUE
... A69: C1770303917569 | B69: Ahmed Gamal | C69: 0589634511 | D69: 0589634511 | E69: المشرف | F69: المشرف شارع الورد فيلا ٨٨ غرفة ٨ | G69: https://www.google.com/maps?q=24.4344584,54.401376 | H69: 46058.754 | I69: 46157.579 | J69: TRUE
A70: C1770303918569 | B70: عمر سليمان | C70: 0505801401 | D70: 0505801401 | E70: الكورنيش | F70: ابو ظبي الكورنيش خلف برج بينونة بناية 26 شقة 1501 | G70: https://www.google.com/maps?q=24.481979370117188,54.350242614746094 | I70: 46155.965
A71: C1770304580861 | B71: ايمان يوسف | C71: 0547612588 | D71: 0547612588 | E71: الشوامخ | F71: شوامخ 5قريب اللولو | G71: https://www.google.com/maps?q=24.346395900789,54.64706009484143 | H71: 46058.761 | I71: 46159.075 | J71: TRUE
A72: C1770305665632 | B72: نور الهدي عزت | C72: 0507302615 | D72: 0507302615 | E72: مدينة خليفة | F72: عمارات الاتحاد بلازا شارع المريف عمارة رقم C64 شقة 602 | G72: https://www.google.com/maps?q=24.44385204922594,54.61288605394732 | H72: 46058.774 | I72: 46074.796 | J72: TRUE
A73: C1770305665633 | B73: تقي خالد ابراهيم | C73: 0545592383 | D73: 0545592383 | E73: مصفح | F73: ابوظبي/شعبيه١٢/ مبني ٢٧٧ / شقه ٦٠٤ | G73: https://www.google.com/maps?q=24.318532943725586,54.537132263183594 | I73: 46160.762
A74: C1770306711005 | B74: عبدالرحمن السعودى | C74: 0552061749 | D74: 0552061749 | E74: الشهامه الجديده | F74: 2شارع الاخيل -ملحق فيلا 233 -الطابق الاخير -شقة 105 | G74: https://www.google.com/maps?q=24.536588668823242,54.68614196777344 | H74: 46058.786 | I74: 46058.786 | J74: TRUE
A75: C1770307868364 | B75: كريم علي | C75: 0505133865 | D75: 0505133865 | E75: جزيرة الريم | F75: مانجروف بالاس شقه ٨٢١ | G75: https://www.google.com/maps?q=24.496540069580078,54.408409118652344 | H75: 46058.799 | I75: 46058.879 | J75: TRUE
A76: C1770308402737 | B76: Eman Raafat | C76: 0554674936 | D76: 0554674936 | E76: Al Dhana | F76: flat 701. Burj Al souq building, behind WTC mall corniche side. Same building of Global dry clean | G76: https://www.google.com/maps?q=24.489546362342328,54.35587070993883 | H76: 46058.806 | I76: 46146.785 | J76: TRUE
A77: C1770309813167 | B77: محمد الدالي | C77: 0568007221 | D77: 0568007221 | E77: الخالدية | F77: ابو ظبي الخالديه شارع الفلاح فيلا ٦ غرفه ١٠ | G77: https://www.google.com/maps?q=24.463097361118965,54.350282867429875 | H77: 46058.822 | I77: 46058.826 | J77: TRUE
A78: C1770310815685 | B78: ندى هشام | C78: 0582002273 | D78: 0582002273 | E78: محمد بن زايد | F78: العنوان ابوظبي محمد بن زايد حوض ٢٧ فيلا ٤٧ | G78: https://www.google.com/maps?q=24.310261,54.539455 | H78: 46058.833 | I78: 46129.761 | J78: TRUE
A79: C1770315803072 | B79: سعاد شبل | C79: 0547669820 | D79: 0547669820 | E79: مدينه مصدر | F79: تاون هاوس 35، ذا جيت، مصدر ، ابو ظبي | G79: https://www.google.com/maps?q=24.4366151,54.6181868 | H79: 46058.891 | I79: 46138.493 | J79: TRUE
A80: C1770317077469 | B80: رباب عبد الرحمن | C80: 0505805381 | D80: 0505805381 | E80: ال نهيان | F80: ال نهيان تنكر المياة / شارع الغلا بناية رقم ٦ بناية مطعم نسائم النيلين/ شقة ٣٠٤ | G80: https://www.google.com/maps?q=24.462725234516206,54.382288793354874 | H80: 46058.906 | I80: 46151.599 | J80: TRUE
A81: C1770317280844 | B81: شروق خليل | C81: 0507113904 | D81: 0507113904 | E81: كورنيش ابوظبي | F81: كورنيش تقاطع الخليج العربي بناية زادكو بلوكD شقه 904 | G81: https://www.google.com/maps?q=24.47131165461526,54.34203693592048 | H81: 46058.908 | I81: 46059.872 | J81: TRUE
...

Sheet AlRoknAlMasry

Sheet Orders
A1: OrderID | B1: CustomerID | C1: Items | D1: Name | E1: Phone | F1: OrderDate | G1: Status | H1: OrderDate

Sheet AlFayoumi
A1: OrderID | B1: CustomerID | C1: Items | D1: Name | E1: Phone | F1: OrderDate | G1: Status | H1: OrderDate
A2: O1779018370262 | B2: C1776884700619 | C2: 20 دجاجه وزن ١٢٠٠ سعر الدجاجه ٢٠ درهم كل دجاجه لحالها | D2: ملك عمرو | E2: 0523020946 | F2: 46159.657 | G2: تم التحديث | H2: 46161.675 | J2: https://www.google.com/maps?q=24.476906066431106,54.367972972393915 | O2: fayoumi
A3: O1779191777788 | B3: C1779191613438 | C3: 6فرخات بيضه وزن. ١٢٠٠ | D3: ساره ذكى | E3: 0569233207 | F3: 46161.664 | G3: جديد | H3: 46161.664 | J3: https://www.google.com/maps?q=24.333568155473717,54.71084769152754 | O3: fayoumi
A4: O1779192174812 | B4: C1778181837755 | C4: 12دجاجة وزن 1200سعر 20درهم | D4: هاجر السيد | E4: 0508168275 | F4: 46161.669 | G4: جديد | H4: 46161.669 | J4: https://www.google.com/maps?q=24.32160286901728,54.62401405136186 | O4: fayoumi
A5: O1779192335543 | B5: C1768653088625 | C5: عوزه 10فرخات 1500الي 1600 2كيلو رجول | D5: شيماء | E5: 0529157624 | F5: 46161.67 | G5: جديد | H5: 46161.67 | J5: https://www.google.com/maps?q=24.489808806913402,54.379773574784124 | O5: fayoumi
A6: O1779192763177 | B6: C1778325015999 | C6: عدد 5 دجاج ابيضّ وزن 1200 كيلو بانيه كل نص لوحده كيلو صدور بدون عظم كل نصف لوحده | D6: Esraa Elwakel | E6: 0528204091 | F6: 46161.675 | G6: جديد | H6: 46161.675 | J6: https://www.google.com/maps?q=24.405996821373577,54.517312166606 | O6: fayoumi
A7: O1779196437405 | B7: C1769324778781 | C7: ٤ كيلو بانيه مش متقطع ٤ كيلو اوراك وزن ١٥٠٠ كل كيلو لوحده | D7: Eman Elkoumy | E7: 0529391713 | F7: 46161.718 | G7: جديد | H7: 46161.718 | J7: https://www.google.com/maps?q=24.4907523,54.4000173 | O7: fayoumi
A8: O1779206737453 | B8: C1778243253026 | C8: ١٢ دجاجه بيضا وزن ١٢٠٠ | D8: دعاء صالح | E8: 0557827324 | F8: 46161.837 | G8: جديد | H8: 46161.837 | J8: https://www.google.com/maps?q=24.4839877,54.3736343 | O8: fayoumi
A9: O1779219097726 | B9: C1776515849146 | C9: ٥ فراخ أبيض وزن 1700_1800 نص كيلو رجل | D9: هاجر محمد | E9: 0502358249 | F9: 46161.98 | G9: جديد | H9: 46161.98 | J9: https://www.google.com/maps?q=24.4018107,54.519146 | O9: fayoumi
A10: O1779249920181 | B10: C1770412918700 | C10: ٥ دجاج أبيض من ١٥٠٠-١٦٠٠ | D10: Heba Motawea | E10: 0564507569 | F10: 46162.337 | G10: جديد | H10: 46162.337 | J10: https://www.google.com/maps?q=24.3795837,54.6433836 | O10: fayoumi
A11: O1779285905718 | B11: C1768655293606 | C11: 3 فراخات 1200 جرام | D11: Naglaa Eslam | E11: 0555060297 | F11: 46162.753 | G11: جديد | H11: 46162.753 | J11: https://www.google.com/maps?q=24.396056135766734,54.5660779698686 | O11: fayoumi
A12: O1779289844939 | B12: C1776633916549 | C12: ٢ كيلو صدور سليمه مش متقطعه ٣ فرخات من ١٧٠٠الي ١٨٠٠ | D12: Aya | E12: 0585284234 | F12: 46162.799 | G12: جديد | H12: 46162.799 | J12: https://www.google.com/maps?q=24.413685,54.495136 | O12: fayoumi
N15: 2 جوز حمام وفردة حمام ٢ ديك بلدي يكونوا ١٥٠٠ ديك ابيض ١٦٠٠ يتقطع ٨ قطع كيلو بانيه يكون رفيع نصف كيلو كبد وقوانص
N16: اللي كانت طالبه 35 دجاجة خليتهم 20 بس

Sheet Workspace
A1: OrderID | B1: CustomerID | C1: Order | D1: Mobile | E1: Name | F1: Area | G1: Address | H1: Location | I1: Sep-Text | J1: Oroder | L1: Order | M1: Name | N1: Name
A2: =#REF! -> #REF! | B2: =#REF! -> #REF! | C2: =IFERROR(VLOOKUP(B2, Routes!B:G, 6, FALSE), "") | D2: =VLOOKUP(A2, Orders!A:O, 5, FALSE) -> #REF! | E2: =VLOOKUP(A2, Orders!A:O, 4, FALSE) -> #REF! | F2: =IFERROR(VLOOKUP(B2, DataBase!A:O, 5, FALSE), "No Order Found") -> No Order Found | G2: =IFERROR(VLOOKUP(B2, DataBase!A:O, 6, FALSE), "No Order Found") -> No Order Found | H2: =IFERROR(VLOOKUP(B2, DataBase!A:O, 7, FALSE), "No Order Found") -> No Order Found | I2: الاوردر👇 | J2: =IFERROR(VLOOKUP(A2, Orders!A:O, 3, FALSE), "No Order Found") -> No Order Found | K2: ="🧾 رقم " & C2 & CHAR(10) & "📞 " & D2 & CHAR(10) & "👤 " & E2 & CHAR(10) & "📍 " & F2 & " - " & G2 & CHAR(10) & "🗺️ " & H2 & CHAR(10) & "🛒 الاوردر 👇" & CHAR(10) & J2 & CHAR(10) & "---------------------------" -> #REF! | L2: 12 | M2: فاطمه ماهر | N2: محمد النجار
A3: =#REF! -> #REF! | B3: =#REF! -> #REF! | C3: =IFERROR(VLOOKUP(B3, Routes!B:G, 6, FALSE), "") | D3: =VLOOKUP(A3, Orders!A:O, 5, FALSE) -> #REF! | E3: =VLOOKUP(A3, Orders!A:O, 4, FALSE) -> #REF! | F3: =IFERROR(VLOOKUP(B3, DataBase!A:O, 5, FALSE), "No Order Found") -> No Order Found | G3: =IFERROR(VLOOKUP(B3, DataBase!A:O, 6, FALSE), "No Order Found") -> No Order Found | H3: =IFERROR(VLOOKUP(B3, DataBase!A:O, 7, FALSE), "No Order Found") -> No Order Found | I3: الاوردر👇 | J3: =IFERROR(VLOOKUP(A3, Orders!A:O, 3, FALSE), "No Order Found") -> No Order Found | K3: ="🧾 رقم " & C3 & CHAR(10) & "📞 " & D3 & CHAR(10) & "👤 " & E3 & CHAR(10) & "📍 " & F3 & " - " & G3 & CHAR(10) & "🗺️ " & H3 & CHAR(10) & "🛒 الاوردر 👇" & CHAR(10) & J3 & CHAR(10) & "---------------------------" -> #REF! | L3: 6 | M3: ريهام احمد | N3: Shimaa Rubishy
A4: =#REF! -> #REF! | B4: =#REF! -> #REF! | C4: =IFERROR(VLOOKUP(B4, Routes!B:G, 6, FALSE), "") | D4: =VLOOKUP(A4, Orders!A:O, 5, FALSE) -> #REF! | E4: =VLOOKUP(A4, Orders!A:O, 4, FALSE) -> #REF! | F4: =IFERROR(VLOOKUP(B4, DataBase!A:O, 5, FALSE), "No Order Found") -> No Order Found | G4: =IFERROR(VLOOKUP(B4, DataBase!A:O, 6, FALSE), "No Order Found") -> No Order Found | H4: =IFERROR(VLOOKUP(B4, DataBase!A:O, 7, FALSE), "No Order Found") -> No Order Found | I4: الاوردر👇 | J4: =IFERROR(VLOOKUP(A4, Orders!A:O, 3, FALSE), "No Order Found") -> No Order Found | K4: ="🧾 رقم " & C4 & CHAR(10) & "📞 " & D4 & CHAR(10) & "👤 " & E4 & CHAR(10) & "📍 " & F4 & " - " & G4 & CHAR(10) & "🗺️ " & H4 & CHAR(10) & "🛒 الاوردر 👇" & CHAR(10) & J4 & CHAR(10) & "---------------------------" -> #REF! | L4: 15 | M4: عمر سليمان | N4: حنان محمد
A5: =#REF! -> #REF! | B5: =#REF! -> #REF! | C5: =IFERROR(VLOOKUP(B5, Routes!B:G, 6, FALSE), "") | D5: =VLOOKUP(A5, Orders!A:O, 5, FALSE) -> #REF! | E5: =VLOOKUP(A5, Orders!A:O, 4, FALSE) -> #REF! | F5: =IFERROR(VLOOKUP(B5, DataBase!A:O, 5, FALSE), "No Order Found") -> No Order Found | G5: =IFERROR(VLOOKUP(B5, DataBase!A:O, 6, FALSE), "No Order Found") -> No Order Found | H5: =IFERROR(VLOOKUP(B5, DataBase!A:O, 7, FALSE), "No Order Found") -> No Order Found | I5: الاوردر👇 | J5: =IFERROR(VLOOKUP(A5, Orders!A:O, 3, FALSE), "No Order Found") -> No Order Found | K5: ="🧾 رقم " & C5 & CHAR(10) & "📞 " & D5 & CHAR(10) & "👤 " & E5 & CHAR(10) & "📍 " & F5 & " - " & G5 & CHAR(10) & "🗺️ " & H5 & CHAR(10) & "🛒 الاوردر 👇" & CHAR(10) & J5 & CHAR(10) & "---------------------------" -> #REF! | L5: 16 | M5: Safa fawal | N5: رانا يسري حسن
A6: =#REF! -> #REF! | B6: =#REF! -> #REF! | C6: =IFERROR(VLOOKUP(B6, Routes!B:G, 6, FALSE), "") | D6: =VLOOKUP(A6, Orders!A:O, 5, FALSE) -> #REF! | E6: =VLOOKUP(A6, Orders!A:O, 4, FALSE) -> #REF! | F6: =IFERROR(VLOOKUP(B6, DataBase!A:O, 5, FALSE), "No Order Found") -> No Order Found | G6: =IFERROR(VLOOKUP(B6, DataBase!A:O, 6, FALSE), "No Order Found") -> No Order Found | H6: =IFERROR(VLOOKUP(B6, DataBase!A:O, 7, FALSE), "No Order Found") -> No Order Found | I6: الاوردر👇 | J6: =IFERROR(VLOOKUP(A6, Orders!A:O, 3, FALSE), "No Order Found") -> No Order Found | K6: ="🧾 رقم " & C6 & CHAR(10) & "📞 " & D6 & CHAR(10) & "👤 " & E6 & CHAR(10) & "📍 " & F6 & " - " & G6 & CHAR(10) & "🗺️ " & H6 & CHAR(10) & "🛒 الاوردر 👇" & CHAR(10) & J6 & CHAR(10) & "---------------------------" -> #REF! | L6: 5 | M6: Mona | N6: د. إيمان الجندي
A7: =#REF! -> #REF! | B7: =#REF! -> #REF! | C7: =IFERROR(VLOOKUP(B7, Routes!B:G, 6, FALSE), "") | D7: =VLOOKUP(A7, Orders!A:O, 5, FALSE) -> #REF! | E7: =VLOOKUP(A7, Orders!A:O, 4, FALSE) -> #REF! | F7: =IFERROR(VLOOKUP(B7, DataBase!A:O, 5, FALSE), "No Order Found") -> No Order Found | G7: =IFERROR(VLOOKUP(B7, DataBase!A:O, 6, FALSE), "No Order Found") -> No Order Found | H7: =IFERROR(VLOOKUP(B7, DataBase!A:O, 7, FALSE), "No Order Found") -> No Order Found | I7: الاوردر👇 | J7: =IFERROR(VLOOKUP(A7, Orders!A:O, 3, FALSE), "No Order Found") -> No Order Found | K7: ="🧾 رقم " & C7 & CHAR(10) & "📞 " & D7 & CHAR(10) & "👤 " & E7 & CHAR(10) & "📍 " & F7 & " - " & G7 & CHAR(10) & "🗺️ " & H7 & CHAR(10) & "🛒 الاوردر 👇" & CHAR(10) & J7 & CHAR(10) & "---------------------------" -> #REF! | L7: 20 | M7: محمد احمد | N7: Nashwa
A8: =#REF! -> #REF! | B8: =#REF! -> #REF! | C8: =IFERROR(VLOOKUP(B8, Routes!B:G, 6, FALSE), "") | D8: =VLOOKUP(A8, Orders!A:O, 5, FALSE) -> #REF! | E8: =VLOOKUP(A8, Orders!A:O, 4, FALSE) -> #REF! | F8: =IFERROR(VLOOKUP(B8, DataBase!A:O, 5, FALSE), "No Order Found") -> No Order Found | G8: =IFERROR(VLOOKUP(B8, DataBase!A:O, 6, FALSE), "No Order Found") -> No Order Found | H8: =IFERROR(VLOOKUP(B8, DataBase!A:O, 7, FALSE), "No Order Found") -> No Order Found | I8: الاوردر👇 | J8: =IFERROR(VLOOKUP(A8, Orders!A:O, 3, FALSE), "No Order Found") -> No Order Found | K8: ="🧾 رقم " & C8 & CHAR(10) & "📞 " & D8 & CHAR(10) & "👤 " & E8 & CHAR(10) & "📍 " & F8 & " - " & G8 & CHAR(10) & "🗺️ " & H8 & CHAR(10) & "🛒 الاوردر 👇" & CHAR(10) & J8 & CHAR(10) & "---------------------------" -> #REF! | L8: 4 | M8: Intisar Alazzeh | N8: Rania
A9: =#REF! -> #REF! | B9: =#REF! -> #REF! | C9: =IFERROR(VLOOKUP(B9, Routes!B:G, 6, FALSE), "") | D9: =VLOOKUP(A9, Orders!A:O, 5, FALSE) -> #REF! | E9: =VLOOKUP(A9, Orders!A:O, 4, FALSE) -> #REF! | F9: =IFERROR(VLOOKUP(B9, DataBase!A:O, 5, FALSE), "No Order Found") -> No Order Found | G9: =IFERROR(VLOOKUP(B9, DataBase!A:O, 6, FALSE), "No Order Found") -> No Order Found | H9: =IFERROR(VLOOKUP(B9, DataBase!A:O, 7, FALSE), "No Order Found") -> No Order Found | I9: الاوردر👇 | J9: =IFERROR(VLOOKUP(A9, Orders!A:O, 3, FALSE), "No Order Found") -> No Order Found | K9: ="🧾 رقم " & C9 & CHAR(10) & "📞 " & D9 & CHAR(10) & "👤 " & E9 & CHAR(10) & "📍 " & F9 & " - " & G9 & CHAR(10) & "🗺️ " & H9 & CHAR(10) & "🛒 الاوردر 👇" & CHAR(10) & J9 & CHAR(10) & "---------------------------" -> #REF! | L9: 14 | M9: ابو سيف | N9: وهب
A10: =#REF! -> #REF! | B10: =#REF! -> #REF! | C10: =IFERROR(VLOOKUP(B10, Routes!B:G, 6, FALSE), "") | D10: =VLOOKUP(A10, Orders!A:O, 5, FALSE) -> #REF! | E10: =VLOOKUP(A10, Orders!A:O, 4, FALSE) -> #REF! | F10: =IFERROR(VLOOKUP(B10, DataBase!A:O, 5, FALSE), "No Order Found") -> No Order Found | G10: =IFERROR(VLOOKUP(B10, DataBase!A:O, 6, FALSE), "No Order Found") -> No Order Found | H10: =IFERROR(VLOOKUP(B10, DataBase!A:O, 7, FALSE), "No Order Found") -> No Order Found | I10: الاوردر👇 | J10: =IFERROR(VLOOKUP(A10, Orders!A:O, 3, FALSE), "No Order Found") -> No Order Found | K10: ="🧾 رقم " & C10 & CHAR(10) & "📞 " & D10 & CHAR(10) & "👤 " & E10 & CHAR(10) & "📍 " & F10 & " - " & G10 & CHAR(10) & "🗺️ " & H10 & CHAR(10) & "🛒 الاوردر 👇" & CHAR(10) & J10 & CHAR(10) & "---------------------------" -> #REF! | L10: 3 | M10: سمر وفيق محمد
A11: =#REF! -> #REF! | B11: =#REF! -> #REF! | C11: =IFERROR(VLOOKUP(B11, Routes!B:G, 6, FALSE), "") | D11: =VLOOKUP(A11, Orders!A:O, 5, FALSE) -> #REF! | E11: =VLOOKUP(A11, Orders!A:O, 4, FALSE) -> #REF! | F11: =IFERROR(VLOOKUP(B11, DataBase!A:O, 5, FALSE), "No Order Found") -> No Order Found | G11: =IFERROR(VLOOKUP(B11, DataBase!A:O, 6, FALSE), "No Order Found") -> No Order Found | H11: =IFERROR(VLOOKUP(B11, DataBase!A:O, 7, FALSE), "No Order Found") -> No Order Found | I11: الاوردر👇 | J11: =IFERROR(VLOOKUP(A11, Orders!A:O, 3, FALSE), "No Order Found") -> No Order Found | K11: ="🧾 رقم " & C11 & CHAR(10) & "📞 " & D11 & CHAR(10) & "👤 " & E11 & CHAR(10) & "📍 " & F11 & " - " & G11 & CHAR(10) & "🗺️ " & H11 & CHAR(10) & "🛒 الاوردر 👇" & CHAR(10) & J11 & CHAR(10) & "---------------------------" -> #REF! | L11: 11 | M11: ملك عمرو | N11: Yusef Mohamed
A12: =#REF! -> #REF! | B12: =#REF! -> #REF! | C12: =IFERROR(VLOOKUP(B12, Routes!B:G, 6, FALSE), "") | D12: =VLOOKUP(A12, Orders!A:O, 5, FALSE) -> #REF! | E12: =VLOOKUP(A12, Orders!A:O, 4, FALSE) -> #REF! | F12: =IFERROR(VLOOKUP(B12, DataBase!A:O, 5, FALSE), "No Order Found") -> No Order Found | G12: =IFERROR(VLOOKUP(B12, DataBase!A:O, 6, FALSE), "No Order Found") -> No Order Found | H12: =IFERROR(VLOOKUP(B12, DataBase!A:O, 7, FALSE), "No Order Found") -> No Order Found | I12: الاوردر👇 | J12: =IFERROR(VLOOKUP(A12, Orders!A:O, 3, FALSE), "No Order Found") -> No Order Found | K12: ="🧾 رقم " & C12 & CHAR(10) & "📞 " & D12 & CHAR(10) & "👤 " & E12 & CHAR(10) & "📍 " & F12 & " - " & G12 & CHAR(10) & "🗺️ " & H12 & CHAR(10) & "🛒 الاوردر 👇" & CHAR(10) & J12 & CHAR(10) & "---------------------------" -> #REF! | L12: 7 | M12: ام بلال
A13: =#REF! -> #REF! | B13: =#REF! -> #REF! | C13: =IFERROR(VLOOKUP(B13, Routes!B:G, 6, FALSE), "") | D13: =VLOOKUP(A13, Orders!A:O, 5, FALSE) -> #REF! | E13: =VLOOKUP(A13, Orders!A:O, 4, FALSE) -> #REF! | F13: =IFERROR(VLOOKUP(B13, DataBase!A:O, 5, FALSE), "No Order Found") -> No Order Found | G13: =IFERROR(VLOOKUP(B13, DataBase!A:O, 6, FALSE), "No Order Found") -> No Order Found | H13: =IFERROR(VLOOKUP(B13, DataBase!A:O, 7, FALSE), "No Order Found") -> No Order Found | I13: الاوردر👇 | J13: =IFERROR(VLOOKUP(A13, Orders!A:O, 3, FALSE), "No Order Found") -> No Order Found | K13: ="🧾 رقم " & C13 & CHAR(10) & "📞 " & D13 & CHAR(10) & "👤 " & E13 & CHAR(10) & "📍 " & F13 & " - " & G13 & CHAR(10) & "🗺️ " & H13 & CHAR(10) & "🛒 الاوردر 👇" & CHAR(10) & J13 & CHAR(10) & "---------------------------" -> #REF! | L13: 21 | M13: Aya sayed | N13: محمود مجدي
A14: =#REF! -> #REF! | B14: =#REF! -> #REF! | C14: =IFERROR(VLOOKUP(B14, Routes!B:G, 6, FALSE), "") | D14: =VLOOKUP(A14, Orders!A:O, 5, FALSE) -> #REF! | E14: =VLOOKUP(A14, Orders!A:O, 4, FALSE) -> #REF! | F14: =IFERROR(VLOOKUP(B14, DataBase!A:O, 5, FALSE), "No Order Found") -> No Order Found | G14: =IFERROR(VLOOKUP(B14, DataBase!A:O, 6, FALSE), "No Order Found") -> No Order Found | H14: =IFERROR(VLOOKUP(B14, DataBase!A:O, 7, FALSE), "No Order Found") -> No Order Found | I14: الاوردر👇 | J14: =IFERROR(VLOOKUP(A14, Orders!A:O, 3, FALSE), "No Order Found") -> No Order Found | K14: ="🧾 رقم " & C14 & CHAR(10) & "📞 " & D14 & CHAR(10) & "👤 " & E14 & CHAR(10) & "📍 " & F14 & " - " & G14 & CHAR(10) & "🗺️ " & H14 & CHAR(10) & "🛒 الاوردر 👇" & CHAR(10) & J14 & CHAR(10) & "---------------------------" -> #REF! | L14: 10 | M14: Samar youssef | N14: علي الجالي
A15: =#REF! -> #REF! | B15: =#REF! -> #REF! | C15: =IFERROR(VLOOKUP(B15, Routes!B:G, 6, FALSE), "") | D15: =VLOOKUP(A15, Orders!A:O, 5, FALSE) -> #REF! | E15: =VLOOKUP(A15, Orders!A:O, 4, FALSE) -> #REF! | F15: =IFERROR(VLOOKUP(B15, DataBase!A:O, 5, FALSE), "No Order Found") -> No Order Found | G15: =IFERROR(VLOOKUP(B15, DataBase!A:O, 6, FALSE), "No Order Found") -> No Order Found | H15: =IFERROR(VLOOKUP(B15, DataBase!A:O, 7, FALSE), "No Order Found") -> No Order Found | I15: الاوردر👇 | J15: =IFERROR(VLOOKUP(A15, Orders!A:O, 3, FALSE), "No Order Found") -> No Order Found | K15: ="🧾 رقم " & C15 & CHAR(10) & "📞 " & D15 & CHAR(10) & "👤 " & E15 & CHAR(10) & "📍 " & F15 & " - " & G15 & CHAR(10) & "🗺️ " & H15 & CHAR(10) & "🛒 الاوردر 👇" & CHAR(10) & J15 & CHAR(10) & "---------------------------" -> #REF! | L15: 19 | M15: نورا هيكل
A16: =#REF! -> #REF! | B16: =#REF! -> #REF! | C16: =IFERROR(VLOOKUP(B16, Routes!B:G, 6, FALSE), "") | D16: =VLOOKUP(A16, Orders!A:O, 5, FALSE) -> #REF! | E16: =VLOOKUP(A16, Orders!A:O, 4, FALSE) -> #REF! | F16: =IFERROR(VLOOKUP(B16, DataBase!A:O, 5, FALSE), "No Order Found") -> No Order Found | G16: =IFERROR(VLOOKUP(B16, DataBase!A:O, 6, FALSE), "No Order Found") -> No Order Found | H16: =IFERROR(VLOOKUP(B16, DataBase!A:O, 7, FALSE), "No Order Found") -> No Order Found | I16: الاوردر👇 | J16: =IFERROR(VLOOKUP(A16, Orders!A:O, 3, FALSE), "No Order Found") -> No Order Found | K16: ="🧾 رقم " & C16 & CHAR(10) & "📞 " & D16 & CHAR(10) & "👤 " & E16 & CHAR(10) & "📍 " & F16 & " - " & G16 & CHAR(10) & "🗺️ " & H16 & CHAR(10) & "🛒 الاوردر 👇" & CHAR(10) & J16 & CHAR(10) & "---------------------------" -> #REF! | L16: 9 | M16: Jasmine Behery
A17: =#REF! -> #REF! | B17: =#REF! -> #REF! | C17: =IFERROR(VLOOKUP(B17, Routes!B:G, 6, FALSE), "") | D17: =VLOOKUP(A17, Orders!A:O, 5, FALSE) -> #REF! | E17: =VLOOKUP(A17, Orders!A:O, 4, FALSE) -> #REF! | F17: =IFERROR(VLOOKUP(B17, DataBase!A:O, 5, FALSE), "No Order Found") -> No Order Found | G17: =IFERROR(VLOOKUP(B17, DataBase!A:O, 6, FALSE), "No Order Found") -> No Order Found | H17: =IFERROR(VLOOKUP(B17, DataBase!A:O, 7, FALSE), "No Order Found") -> No Order Found | I17: الاوردر👇 | J17: =IFERROR(VLOOKUP(A17, Orders!A:O, 3, FALSE), "No Order Found") -> No Order Found | K17: ="🧾 رقم " & C17 & CHAR(10) & "📞 " & D17 & CHAR(10) & "👤 " & E17 & CHAR(10) & "📍 " & F17 & " - " & G17 & CHAR(10) & "🗺️ " & H17 & CHAR(10) & "🛒 الاوردر 👇" & CHAR(10) & J17 & CHAR(10) & "---------------------------" -> #REF! | L17: 8 | M17: عبد الرحمن السيد | N17: دينا عصمت
A18: =#REF! -> #REF! | B18: =#REF! -> #REF! | C18: =IFERROR(VLOOKUP(B18, Routes!B:G, 6, FALSE), "") | D18: =VLOOKUP(A18, Orders!A:O, 5, FALSE) -> #REF! | E18: =VLOOKUP(A18, Orders!A:O, 4, FALSE) -> #REF! | F18: =IFERROR(VLOOKUP(B18, DataBase!A:O, 5, FALSE), "No Order Found") -> No Order Found | G18: =IFERROR(VLOOKUP(B18, DataBase!A:O, 6, FALSE), "No Order Found") -> No Order Found | H18: =IFERROR(VLOOKUP(B18, DataBase!A:O, 7, FALSE), "No Order Found") -> No Order Found | I18: الاوردر👇 | J18: =IFERROR(VLOOKUP(A18, Orders!A:O, 3, FALSE), "No Order Found") -> No Order Found | K18: ="🧾 رقم " & C18 & CHAR(10) & "📞 " & D18 & CHAR(10) & "👤 " & E18 & CHAR(10) & "📍 " & F18 & " - " & G18 & CHAR(10) & "🗺️ " & H18 & CHAR(10) & "🛒 الاوردر 👇" & CHAR(10) & J18 & CHAR(10) & "---------------------------" -> #REF! | L18: 17 | M18: Ossama ElBayoumi
A19: =#REF! -> #REF! | B19: =#REF! -> #REF! | C19: =IFERROR(VLOOKUP(B19, Routes!B:G, 6, FALSE), "") | D19: =VLOOKUP(A19, Orders!A:O, 5, FALSE) -> #REF! | E19: =VLOOKUP(A19, Orders!A:O, 4, FALSE) -> #REF! | F19: =IFERROR(VLOOKUP(B19, DataBase!A:O, 5, FALSE), "No Order Found") -> No Order Found | G19: =IFERROR(VLOOKUP(B19, DataBase!A:O, 6, FALSE), "No Order Found") -> No Order Found | H19: =IFERROR(VLOOKUP(B19, DataBase!A:O, 7, FALSE), "No Order Found") -> No Order Found | I19: الاوردر👇 | J19: =IFERROR(VLOOKUP(A19, Orders!A:O, 3, FALSE), "No Order Found") -> No Order Found | K19: ="🧾 رقم " & C19 & CHAR(10) & "📞 " & D19 & CHAR(10) & "👤 " & E19 & CHAR(10) & "📍 " & F19 & " - " & G19 & CHAR(10) & "🗺️ " & H19 & CHAR(10) & "🛒 الاوردر 👇" & CHAR(10) & J19 & CHAR(10) & "---------------------------" -> #REF! | L19: 22 | M19: Hadeer abdelaaty | N19: Doaa Hammad
A20: =#REF! -> #REF! | B20: =#REF! -> #REF! | C20: =IFERROR(VLOOKUP(B20, Routes!B:G, 6, FALSE), "") | D20: =VLOOKUP(A20, Orders!A:O, 5, FALSE) -> #REF! | E20: =VLOOKUP(A20, Orders!A:O, 4, FALSE) -> #REF! | F20: =IFERROR(VLOOKUP(B20, DataBase!A:O, 5, FALSE), "No Order Found") -> No Order Found | G20: =IFERROR(VLOOKUP(B20, DataBase!A:O, 6, FALSE), "No Order Found") -> No Order Found | H20: =IFERROR(VLOOKUP(B20, DataBase!A:O, 7, FALSE), "No Order Found") -> No Order Found | I20: الاوردر👇 | J20: =IFERROR(VLOOKUP(A20, Orders!A:O, 3, FALSE), "No Order Found") -> No Order Found | K20: ="🧾 رقم " & C20 & CHAR(10) & "📞 " & D20 & CHAR(10) & "👤 " & E20 & CHAR(10) & "📍 " & F20 & " - " & G20 & CHAR(10) & "🗺️ " & H20 & CHAR(10) & "🛒 الاوردر 👇" & CHAR(10) & J20 & CHAR(10) & "---------------------------" -> #REF! | L20: 13 | M20: كيرولس جورج | N20: اسماء شوقي
A21: =#REF! -> #REF! | B21: =#REF! -> #REF! | C21: =IFERROR(VLOOKUP(B21, Routes!B:G, 6, FALSE), "") | D21: =VLOOKUP(A21, Orders!A:O, 5, FALSE) -> #REF! | E21: =VLOOKUP(A21, Orders!A:O, 4, FALSE) -> #REF! | F21: =IFERROR(VLOOKUP(B21, DataBase!A:O, 5, FALSE), "No Order Found") -> No Order Found | G21: =IFERROR(VLOOKUP(B21, DataBase!A:O, 6, FALSE), "No Order Found") -> No Order Found | H21: =IFERROR(VLOOKUP(B21, DataBase!A:O, 7, FALSE), "No Order Found") -> No Order Found | I21: الاوردر👇 | J21: =IFERROR(VLOOKUP(A21, Orders!A:O, 3, FALSE), "No Order Found") -> No Order Found | K21: ="🧾 رقم " & C21 & CHAR(10) & "📞 " & D21 & CHAR(10) & "👤 " & E21 & CHAR(10) & "📍 " & F21 & " - " & G21 & CHAR(10) & "🗺️ " & H21 & CHAR(10) & "🛒 الاوردر 👇" & CHAR(10) & J21 & CHAR(10) & "---------------------------" -> #REF! | L21: 18 | M21: Shima | N21: #N/A
A22: =#REF! -> #REF! | B22: =#REF! -> #REF! | C22: =IFERROR(VLOOKUP(B22, Routes!B:G, 6, FALSE), "") | D22: =VLOOKUP(A22, Orders!A:O, 5, FALSE) -> #REF! | E22: =VLOOKUP(A22, Orders!A:O, 4, FALSE) -> #REF! | F22: =IFERROR(VLOOKUP(B22, DataBase!A:O, 5, FALSE), "No Order Found") -> No Order Found | G22: =IFERROR(VLOOKUP(B22, DataBase!A:O, 6, FALSE), "No Order Found") -> No Order Found | H22: =IFERROR(VLOOKUP(B22, DataBase!A:O, 7, FALSE), "No Order Found") -> No Order Found | I22: الاوردر👇 | J22: =IFERROR(VLOOKUP(A22, Orders!A:O, 3, FALSE), "No Order Found") -> No Order Found | K22: ="🧾 رقم " & C22 & CHAR(10) & "📞 " & D22 & CHAR(10) & "👤 " & E22 & CHAR(10) & "📍 " & F22 & " - " & G22 & CHAR(10) & "🗺️ " & H22 & CHAR(10) & "🛒 الاوردر 👇" & CHAR(10) & J22 & CHAR(10) & "---------------------------" -> #REF! | L22: 23 | M22: محمود الرفاعي | N22: #N/A
A23: =#REF! -> #REF! | B23: =#REF! -> #REF! | C23: =IFERROR(VLOOKUP(B23, Routes!B:G, 6, FALSE), "") | D23: =VLOOKUP(A23, Orders!A:O, 5, FALSE) -> #REF! | E23: =VLOOKUP(A23, Orders!A:O, 4, FALSE) -> #REF! | F23: =IFERROR(VLOOKUP(B23, DataBase!A:O, 5, FALSE), "No Order Found") -> No Order Found | G23: =IFERROR(VLOOKUP(B23, DataBase!A:O, 6, FALSE), "No Order Found") -> No Order Found | H23: =IFERROR(VLOOKUP(B23, DataBase!A:O, 7, FALSE), "No Order Found") -> No Order Found | I23: الاوردر👇 | J23: =IFERROR(VLOOKUP(A23, Orders!A:O, 3, FALSE), "No Order Found") -> No Order Found | K23: ="🧾 رقم " & C23 & CHAR(10) & "📞 " & D23 & CHAR(10) & "👤 " & E23 & CHAR(10) & "📍 " & F23 & " - " & G23 & CHAR(10) & "🗺️ " & H23 & CHAR(10) & "🛒 الاوردر 👇" & CHAR(10) & J23 & CHAR(10) & "---------------------------" -> #REF! | L23: 2 | M23: Enas | N23: نسمة السعيد السعيد
A24: =#REF! -> #REF! | B24: =#REF! -> #REF! | C24: =IFERROR(VLOOKUP(B24, Routes!B:G, 6, FALSE), "") | D24: =VLOOKUP(A24, Orders!A:O, 5, FALSE) -> #REF! | E24: =VLOOKUP(A24, Orders!A:O, 4, FALSE) -> #REF! | F24: =IFERROR(VLOOKUP(B24, DataBase!A:O, 5, FALSE), "No Order Found") -> No Order Found | G24: =IFERROR(VLOOKUP(B24, DataBase!A:O, 6, FALSE), "No Order Found") -> No Order Found | H24: =IFERROR(VLOOKUP(B24, DataBase!A:O, 7, FALSE), "No Order Found") -> No Order Found | I24: الاوردر👇 | J24: =IFERROR(VLOOKUP(A24, Orders!A:O, 3, FALSE), "No Order Found") -> No Order Found | K24: ="🧾 رقم " & C24 & CHAR(10) & "📞 " & D24 & CHAR(10) & "👤 " & E24 & CHAR(10) & "📍 " & F24 & " - " & G24 & CHAR(10) & "🗺️ " & H24 & CHAR(10) & "🛒 الاوردر 👇" & CHAR(10) & J24 & CHAR(10) & "---------------------------" -> #REF! | L24: 1 | M24: محمد النجار | N24: #N/A
A25: =#REF! -> #REF! | B25: =#REF! -> #REF! | C25: =IFERROR(VLOOKUP(B25, Routes!B:G, 6, FALSE), "") | D25: =VLOOKUP(A25, Orders!A:O, 5, FALSE) -> #REF! | E25: =VLOOKUP(A25, Orders!A:O, 4, FALSE) -> #REF! | F25: =IFERROR(VLOOKUP(B25, DataBase!A:O, 5, FALSE), "No Order Found") -> No Order Found | G25: =IFERROR(VLOOKUP(B25, DataBase!A:O, 6, FALSE), "No Order Found") -> No Order Found | H25: =IFERROR(VLOOKUP(B25, DataBase!A:O, 7, FALSE), "No Order Found") -> No Order Found | I25: الاوردر👇 | J25: =IFERROR(VLOOKUP(A25, Orders!A:O, 3, FALSE), "No Order Found") -> No Order Found | K25: ="🧾 رقم " & C25 & CHAR(10) & "📞 " & D25 & CHAR(10) & "👤 " & E25 & CHAR(10) & "📍 " & F25 & " - " & G25 & CHAR(10) & "🗺️ " & H25 & CHAR(10) & "🛒 الاوردر 👇" & CHAR(10) & J25 & CHAR(10) & "---------------------------" -> #REF! | L25: 24 | M25: حنان محمد | N25: صفاء مصطفي
A26: =#REF! -> #REF! | B26: =#REF! -> #REF! | C26: =IFERROR(VLOOKUP(B26, Routes!B:G, 6, FALSE), "") | D26: =VLOOKUP(A26, Orders!A:O, 5, FALSE) -> #REF! | E26: =VLOOKUP(A26, Orders!A:O, 4, FALSE) -> #REF! | F26: =IFERROR(VLOOKUP(B26, DataBase!A:O, 5, FALSE), "No Order Found") -> No Order Found | G26: =IFERROR(VLOOKUP(B26, DataBase!A:O, 6, FALSE), "No Order Found") -> No Order Found | H26: =IFERROR(VLOOKUP(B26, DataBase!A:O, 7, FALSE), "No Order Found") -> No Order Found | I26: الاوردر👇 | J26: =IFERROR(VLOOKUP(A26, Orders!A:O, 3, FALSE), "No Order Found") -> No Order Found | K26: ="🧾 رقم " & C26 & CHAR(10) & "📞 " & D26 & CHAR(10) & "👤 " & E26 & CHAR(10) & "📍 " & F26 & " - " & G26 & CHAR(10) & "🗺️ " & H26 & CHAR(10) & "🛒 الاوردر 👇" & CHAR(10) & J26 & CHAR(10) & "---------------------------" -> #REF! | L26: 25 | M26: Walaa Salah | N26: Hend Kishta
A27: =#REF! -> #REF! | B27: =#REF! -> #REF! | C27: =IFERROR(VLOOKUP(B27, Routes!B:G, 6, FALSE), "") | D27: =VLOOKUP(A27, Orders!A:O, 5, FALSE) -> #REF! | E27: =VLOOKUP(A27, Orders!A:O, 4, FALSE) -> #REF! | F27: =IFERROR(VLOOKUP(B27, DataBase!A:O, 5, FALSE), "No Order Found") -> No Order Found | G27: =IFERROR(VLOOKUP(B27, DataBase!A:O, 6, FALSE), "No Order Found") -> No Order Found | H27: =IFERROR(VLOOKUP(B27, DataBase!A:O, 7, FALSE), "No Order Found") -> No Order Found | I27: الاوردر👇 | J27: =IFERROR(VLOOKUP(A27, Orders!A:O, 3, FALSE), "No Order Found") -> No Order Found | K27: ="🧾 رقم " & C27 & CHAR(10) & "📞 " & D27 & CHAR(10) & "👤 " & E27 & CHAR(10) & "📍 " & F27 & " - " & G27 & CHAR(10) & "🗺️ " & H27 & CHAR(10) & "🛒 الاوردر 👇" & CHAR(10) & J27 & CHAR(10) & "---------------------------" -> #REF! | L27: 26 | M27: علي احمد علي سليمان | N27: محمود عبدالوهاب
A28: =#REF! -> #REF! | B28: =#REF! -> #REF! | C28: =IFERROR(VLOOKUP(B28, Routes!B:G, 6, FALSE), "") | D28: =VLOOKUP(A28, Orders!A:O, 5, FALSE) -> #REF! | E28: =VLOOKUP(A28, Orders!A:O, 4, FALSE) -> #REF! | F28: =IFERROR(VLOOKUP(B28, DataBase!A:O, 5, FALSE), "No Order Found") -> No Order Found | G28: =IFERROR(VLOOKUP(B28, DataBase!A:O, 6, FALSE), "No Order Found") -> No Order Found | H28: =IFERROR(VLOOKUP(B28, DataBase!A:O, 7, FALSE), "No Order Found") -> No Order Found | I28: الاوردر👇 | J28: =IFERROR(VLOOKUP(A28, Orders!A:O, 3, FALSE), "No Order Found") -> No Order Found | K28: ="🧾 رقم " & C28 & CHAR(10) & "📞 " & D28 & CHAR(10) & "👤 " & E28 & CHAR(10) & "📍 " & F28 & " - " & G28 & CHAR(10) & "🗺️ " & H28 & CHAR(10) & "🛒 الاوردر 👇" & CHAR(10) & J28 & CHAR(10) & "---------------------------" -> #REF! | L28: 27 | M28: Hanan Gamal | N28: فاطمة جودة
A29: =#REF! -> #REF! | B29: =#REF! -> #REF! | C29: =IFERROR(VLOOKUP(B29, Routes!B:G, 6, FALSE), "") | D29: =VLOOKUP(A29, Orders!A:O, 5, FALSE) -> #REF! | E29: =VLOOKUP(A29, Orders!A:O, 4, FALSE) -> #REF! | F29: =IFERROR(VLOOKUP(B29, DataBase!A:O, 5, FALSE), "No Order Found") -> No Order Found | G29: =IFERROR(VLOOKUP(B29, DataBase!A:O, 6, FALSE), "No Order Found") -> No Order Found | H29: =IFERROR(VLOOKUP(B29, DataBase!A:O, 7, FALSE), "No Order Found") -> No Order Found | I29: الاوردر👇 | J29: =IFERROR(VLOOKUP(A29, Orders!A:O, 3, FALSE), "No Order Found") -> No Order Found | K29: ="🧾 رقم " & C29 & CHAR(10) & "📞 " & D29 & CHAR(10) & "👤 " & E29 & CHAR(10) & "📍 " & F29 & " - " & G29 & CHAR(10) & "🗺️ " & H29 & CHAR(10) & "🛒 الاوردر 👇" & CHAR(10) & J29 & CHAR(10) & "---------------------------" -> #REF! | L29: 28 | M29: Ahmed Gamal | N29: Sara elbehery
A30: =#REF! -> #REF! | B30: =#REF! -> #REF! | C30: =IFERROR(VLOOKUP(B30, Routes!B:G, 6, FALSE), "") | D30: =VLOOKUP(A30, Orders!A:O, 5, FALSE) -> #REF! | E30: =VLOOKUP(A30, Orders!A:O, 4, FALSE) -> #REF! | F30: =IFERROR(VLOOKUP(B30, DataBase!A:O, 5, FALSE), "No Order Found") -> No Order Found | G30: =IFERROR(VLOOKUP(B30, DataBase!A:O, 6, FALSE), "No Order Found") -> No Order Found | H30: =IFERROR(VLOOKUP(B30, DataBase!A:O, 7, FALSE), "No Order Found") -> No Order Found | I30: الاوردر👇 | J30: =IFERROR(VLOOKUP(A30, Orders!A:O, 3, FALSE), "No Order Found") -> No Order Found | K30: ="🧾 رقم " & C30 & CHAR(10) & "📞 " & D30 & CHAR(10) & "👤 " & E30 & CHAR(10) & "📍 " & F30 & " - " & G30 & CHAR(10) & "🗺️ " & H30 & CHAR(10) & "🛒 الاوردر 👇" & CHAR(10) & J30 & CHAR(10) & "---------------------------" -> #REF! | L30: 29 | M30: Yasmin gaber | N30: Tala gasser
A31: =#REF! -> #REF! | B31: =#REF! -> #REF! | C31: =IFERROR(VLOOKUP(B31, Routes!B:G, 6, FALSE), "") | D31: =VLOOKUP(A31, Orders!A:O, 5, FALSE) -> #REF! | E31: =VLOOKUP(A31, Orders!A:O, 4, FALSE) -> #REF! | F31: =IFERROR(VLOOKUP(B31, DataBase!A:O, 5, FALSE), "No Order Found") -> No Order Found | G31: =IFERROR(VLOOKUP(B31, DataBase!A:O, 6, FALSE), "No Order Found") -> No Order Found | H31: =IFERROR(VLOOKUP(B31, DataBase!A:O, 7, FALSE), "No Order Found") -> No Order Found | I31: الاوردر👇 | J31: =IFERROR(VLOOKUP(A31, Orders!A:O, 3, FALSE), "No Order Found") -> No Order Found | K31: ="🧾 رقم " & C31 & CHAR(10) & "📞 " & D31 & CHAR(10) & "👤 " & E31 & CHAR(10) & "📍 " & F31 & " - " & G31 & CHAR(10) & "🗺️ " & H31 & CHAR(10) & "🛒 الاوردر 👇" & CHAR(10) & J31 & CHAR(10) & "---------------------------" -> #REF! | L31: 30 | M31: Sara | N31: عادل
A32: =#REF! -> #REF! | B32: =#REF! -> #REF! | C32: =IFERROR(VLOOKUP(B32, Routes!B:G, 6, FALSE), "") | D32: =VLOOKUP(A32, Orders!A:O, 5, FALSE) -> #REF! | E32: =VLOOKUP(A32, Orders!A:O, 4, FALSE) -> #REF! | F32: =IFERROR(VLOOKUP(B32, DataBase!A:O, 5, FALSE), "No Order Found") -> No Order Found | G32: =IFERROR(VLOOKUP(B32, DataBase!A:O, 6, FALSE), "No Order Found") -> No Order Found | H32: =IFERROR(VLOOKUP(B32, DataBase!A:O, 7, FALSE), "No Order Found") -> No Order Found | I32: الاوردر👇 | J32: =IFERROR(VLOOKUP(A32, Orders!A:O, 3, FALSE), "No Order Found") -> No Order Found | K32: ="🧾 رقم " & C32 & CHAR(10) & "📞 " & D32 & CHAR(10) & "👤 " & E32 & CHAR(10) & "📍 " & F32 & " - " & G32 & CHAR(10) & "🗺️ " & H32 & CHAR(10) & "🛒 الاوردر 👇" & CHAR(10) & J32 & CHAR(10) & "---------------------------" -> #REF! | L32: 31 | M32: Naglaa Eslam | N32: Youssef Shehata
A33: =#REF! -> #REF! | B33: =#REF! -> #REF! | C33: =IFERROR(VLOOKUP(B33, Routes!B:G, 6, FALSE), "") | D33: =VLOOKUP(A33, Orders!A:O, 5, FALSE) -> #REF! | E33: =VLOOKUP(A33, Orders!A:O, 4, FALSE) -> #REF! | F33: =IFERROR(VLOOKUP(B33, DataBase!A:O, 5, FALSE), "No Order Found") -> No Order Found | G33: =IFERROR(VLOOKUP(B33, DataBase!A:O, 6, FALSE), "No Order Found") -> No Order Found | H33: =IFERROR(VLOOKUP(B33, DataBase!A:O, 7, FALSE), "No Order Found") -> No Order Found | I33: الاوردر👇 | J33: =IFERROR(VLOOKUP(A33, Orders!A:O, 3, FALSE), "No Order Found") -> No Order Found | K33: ="🧾 رقم " & C33 & CHAR(10) & "📞 " & D33 & CHAR(10) & "👤 " & E33 & CHAR(10) & "📍 " & F33 & " - " & G33 & CHAR(10) & "🗺️ " & H33 & CHAR(10) & "🛒 الاوردر 👇" & CHAR(10) & J33 & CHAR(10) & "---------------------------" -> #REF! | L33: 32 | M33: منال | N33: دعاء صالح
A34: =#REF! -> #REF! | B34: =#REF! -> #REF! | C34: =IFERROR(VLOOKUP(B34, Routes!B:G, 6, FALSE), "") | D34: =VLOOKUP(A34, Orders!A:O, 5, FALSE) -> #REF! | E34: =VLOOKUP(A34, Orders!A:O, 4, FALSE) -> #REF! | F34: =IFERROR(VLOOKUP(B34, DataBase!A:O, 5, FALSE), "No Order Found") -> No Order Found | G34: =IFERROR(VLOOKUP(B34, DataBase!A:O, 6, FALSE), "No Order Found") -> No Order Found | H34: =IFERROR(VLOOKUP(B34, DataBase!A:O, 7, FALSE), "No Order Found") -> No Order Found | I34: الاوردر👇 | J34: =IFERROR(VLOOKUP(A34, Orders!A:O, 3, FALSE), "No Order Found") -> No Order Found | K34: ="🧾 رقم " & C34 & CHAR(10) & "📞 " & D34 & CHAR(10) & "👤 " & E34 & CHAR(10) & "📍 " & F34 & " - " & G34 & CHAR(10) & "🗺️ " & H34 & CHAR(10) & "🛒 الاوردر 👇" & CHAR(10) & J34 & CHAR(10) & "---------------------------" -> #REF! | L34: 33 | M34: وهب | N34: سمر وفيق محمد
A35: =#REF! -> #REF! | B35: =#REF! -> #REF! | C35: =IFERROR(VLOOKUP(B35, Routes!B:G, 6, FALSE), "") | D35: =VLOOKUP(A35, Orders!A:O, 5, FALSE) -> #REF! | E35: =VLOOKUP(A35, Orders!A:O, 4, FALSE) -> #REF! | F35: =IFERROR(VLOOKUP(B35, DataBase!A:O, 5, FALSE), "No Order Found") -> No Order Found | G35: =IFERROR(VLOOKUP(B35, DataBase!A:O, 6, FALSE), "No Order Found") -> No Order Found | H35: =IFERROR(VLOOKUP(B35, DataBase!A:O, 7, FALSE), "No Order Found") -> No Order Found | I35: الاوردر👇 | J35: =IFERROR(VLOOKUP(A35, Orders!A:O, 3, FALSE), "No Order Found") -> No Order Found | K35: ="🧾 رقم " & C35 & CHAR(10) & "📞 " & D35 & CHAR(10) & "👤 " & E35 & CHAR(10) & "📍 " & F35 & " - " & G35 & CHAR(10) & "🗺️ " & H35 & CHAR(10) & "🛒 الاوردر 👇" & CHAR(10) & J35 & CHAR(10) & "---------------------------" -> #REF! | L35: 34 | M35: شهيرة مجدي
A36: =#REF! -> #REF! | B36: =#REF! -> #REF! | C36: =IFERROR(VLOOKUP(B36, Routes!B:G, 6, FALSE), "") | D36: =VLOOKUP(A36, Orders!A:O, 5, FALSE) -> #REF! | E36: =VLOOKUP(A36, Orders!A:O, 4, FALSE) -> #REF! | F36: =IFERROR(VLOOKUP(B36, DataBase!A:O, 5, FALSE), "No Order Found") -> No Order Found | G36: =IFERROR(VLOOKUP(B36, DataBase!A:O, 6, FALSE), "No Order Found") -> No Order Found | H36: =IFERROR(VLOOKUP(B36, DataBase!A:O, 7, FALSE), "No Order Found") -> No Order Found | I36: الاوردر👇 | J36: =IFERROR(VLOOKUP(A36, Orders!A:O, 3, FALSE), "No Order Found") -> No Order Found | K36: ="🧾 رقم " & C36 & CHAR(10) & "📞 " & D36 & CHAR(10) & "👤 " & E36 & CHAR(10) & "📍 " & F36 & " - " & G36 & CHAR(10) & "🗺️ " & H36 & CHAR(10) & "🛒 الاوردر 👇" & CHAR(10) & J36 & CHAR(10) & "---------------------------" -> #REF! | L36: 35 | M36: Rofyda | N36: عمر سليمان
A37: =#REF! -> #REF! | B37: =#REF! -> #REF! | C37: =IFERROR(VLOOKUP(B37, Routes!B:G, 6, FALSE), "") | D37: =VLOOKUP(A37, Orders!A:O, 5, FALSE) -> #REF! | E37: =VLOOKUP(A37, Orders!A:O, 4, FALSE) -> #REF! | F37: =IFERROR(VLOOKUP(B37, DataBase!A:O, 5, FALSE), "No Order Found") -> No Order Found | G37: =IFERROR(VLOOKUP(B37, DataBase!A:O, 6, FALSE), "No Order Found") -> No Order Found | H37: =IFERROR(VLOOKUP(B37, DataBase!A:O, 7, FALSE), "No Order Found") -> No Order Found | I37: الاوردر👇 | J37: =IFERROR(VLOOKUP(A37, Orders!A:O, 3, FALSE), "No Order Found") -> No Order Found | K37: ="🧾 رقم " & C37 & CHAR(10) & "📞 " & D37 & CHAR(10) & "👤 " & E37 & CHAR(10) & "📍 " & F37 & " - " & G37 & CHAR(10) & "🗺️ " & H37 & CHAR(10) & "🛒 الاوردر 👇" & CHAR(10) & J37 & CHAR(10) & "---------------------------" -> #REF! | L37: 36 | M37: Eslam ali | N37: Eman Raafat
A38: =#REF! -> #REF! | B38: =#REF! -> #REF! | C38: =IFERROR(VLOOKUP(B38, Routes!B:G, 6, FALSE), "") | D38: =VLOOKUP(A38, Orders!A:O, 5, FALSE) -> #REF! | E38: =VLOOKUP(A38, Orders!A:O, 4, FALSE) -> #REF! | F38: =IFERROR(VLOOKUP(B38, DataBase!A:O, 5, FALSE), "No Order Found") -> No Order Found | G38: =IFERROR(VLOOKUP(B38, DataBase!A:O, 6, FALSE), "No Order Found") -> No Order Found | H38: =IFERROR(VLOOKUP(B38, DataBase!A:O, 7, FALSE), "No Order Found") -> No Order Found | I38: الاوردر👇 | J38: =IFERROR(VLOOKUP(A38, Orders!A:O, 3, FALSE), "No Order Found") -> No Order Found | K38: ="🧾 رقم " & C38 & CHAR(10) & "📞 " & D38 & CHAR(10) & "👤 " & E38 & CHAR(10) & "📍 " & F38 & " - " & G38 & CHAR(10) & "🗺️ " & H38 & CHAR(10) & "🛒 الاوردر 👇" & CHAR(10) & J38 & CHAR(10) & "---------------------------" -> #REF! | L38: 37 | M38: محمد العربي | N38: Eman Elkoumy
A39: =Orders!A2 | B39: =Orders!B2 | C39: =IFERROR(VLOOKUP(B39, Routes!B:G, 6, FALSE), "") | D39: =VLOOKUP(A39, Orders!A:O, 5, FALSE) -> #N/A | E39: =VLOOKUP(A39, Orders!A:O, 4, FALSE) -> #N/A | F39: =IFERROR(VLOOKUP(B39, DataBase!A:O, 5, FALSE), "No Order Found") -> No Order Found | G39: =IFERROR(VLOOKUP(B39, DataBase!A:O, 6, FALSE), "No Order Found") -> No Order Found | H39: =IFERROR(VLOOKUP(B39, DataBase!A:O, 7, FALSE), "No Order Found") -> No Order Found | I39: الاوردر👇 | J39: =IFERROR(VLOOKUP(A39, Orders!A:O, 3, FALSE), "No Order Found") -> No Order Found | K39: ="🧾 رقم " & C39 & CHAR(10) & "📞 " & D39 & CHAR(10) & "👤 " & E39 & CHAR(10) & "📍 " & F39 & " - " & G39 & CHAR(10) & "🗺️ " & H39 & CHAR(10) & "🛒 الاوردر 👇" & CHAR(10) & J39 & CHAR(10) & "---------------------------" -> #N/A | L39: 38 | M39: احمد علي | N39: Eman Mohamed
A40: =Orders!A3 | B40: =Orders!B3 | C40: =IFERROR(VLOOKUP(B40, Routes!B:G, 6, FALSE), "") | D40: =VLOOKUP(A40, Orders!A:O, 5, FALSE) -> #N/A | E40: =VLOOKUP(A40, Orders!A:O, 4, FALSE) -> #N/A | F40: =IFERROR(VLOOKUP(B40, DataBase!A:O, 5, FALSE), "No Order Found") -> No Order Found | G40: =IFERROR(VLOOKUP(B40, DataBase!A:O, 6, FALSE), "No Order Found") -> No Order Found | H40: =IFERROR(VLOOKUP(B40, DataBase!A:O, 7, FALSE), "No Order Found") -> No Order Found | I40: الاوردر👇 | J40: =IFERROR(VLOOKUP(A40, Orders!A:O, 3, FALSE), "No Order Found") -> No Order Found | K40: ="🧾 رقم " & C40 & CHAR(10) & "📞 " & D40 & CHAR(10) & "👤 " & E40 & CHAR(10) & "📍 " & F40 & " - " & G40 & CHAR(10) & "🗺️ " & H40 & CHAR(10) & "🛒 الاوردر 👇" & CHAR(10) & J40 & CHAR(10) & "---------------------------" -> #N/A | L40: 39 | M40: محمد رمضان | N40: Lamis Mahmoud
...

Sheet FWorkspace
A1: OrderID | B1: CustomerID | C1: Order | D1: Mobile | E1: Name | F1: Area | G1: Address | H1: Location | I1: Sep-Text | J1: Oroder | L1: Order | M1: Name
A2: =AlFayoumi!A5 -> O1779192335543 | B2: =AlFayoumi!B5 -> C1768653088625 | C2: =IFERROR(VLOOKUP(B2, Routes!B:G, 6, FALSE), "") -> 1 | D2: =VLOOKUP(A2, AlFayoumi!A:O, 5, FALSE) -> 0529157624 | E2: =VLOOKUP(A2, AlFayoumi!A:O, 4, FALSE) -> شيماء | F2: =IFERROR(VLOOKUP(B2, DataBase!A:O, 5, FALSE), "No Order Found") -> Al danah | G2: =IFERROR(VLOOKUP(B2, DataBase!A:O, 6, FALSE), "No Order Found") -> شارع الكترا نفس بناية مطعم الابراهيمي شقة ٥٠٣ | H2: =IFERROR(VLOOKUP(B2, DataBase!A:O, 7, FALSE), "No Order Found") -> https://www.google.com/maps?q=24.488376387234172,54.36703744083892 | I2: الاوردر👇 | J2: =IFERROR(VLOOKUP(A2, AlFayoumi!A:O, 3, FALSE), "No Order Found") -> عوزه 10فرخات 1500الي 1600 2كيلو رجول | K2: ="🧾 رقم " & C2 & CHAR(10) & "📞 " & D2 & CHAR(10) & "👤 " & E2 & CHAR(10) & "📍 " & F2 & " - " & G2 & CHAR(10) & "🗺️ " & H2 & CHAR(10) & "🛒 الاوردر 👇" & CHAR(10) & J2 & CHAR(10) & "---------------------------" -> 🧾 رقم 1 📞 0529157624 👤 شيماء 📍 Al danah - شارع الكترا نفس بناية مطعم الابراهيمي شقة ٥٠٣ 🗺️ https://www.google.com/maps?q=24.488376387234172,54.36703744083892 🛒 الاوردر 👇 عوزه 10فرخات 1500الي 1600 2كيلو رجول --------------------------- | L2: 1 | M2: شيماء | N2: كده الاوردرات اللي هتستلم | O2: Mai Hamed
A3: =AlFayoumi!A2 -> O1779018370262 | B3: =AlFayoumi!B2 -> C1776884700619 | C3: =IFERROR(VLOOKUP(B3, Routes!B:G, 6, FALSE), "") -> 2 | D3: =VLOOKUP(A3, AlFayoumi!A:O, 5, FALSE) -> 0523020946 | E3: =VLOOKUP(A3, AlFayoumi!A:O, 4, FALSE) -> ملك عمرو | F3: =IFERROR(VLOOKUP(B3, DataBase!A:O, 5, FALSE), "No Order Found") -> امام شارع الدفاع | G3: =IFERROR(VLOOKUP(B3, DataBase!A:O, 6, FALSE), "No Order Found") -> شارع الفلاح مقابل وير مارت بنايه فريش بالاس الطابق 1408 | H3: =IFERROR(VLOOKUP(B3, DataBase!A:O, 7, FALSE), "No Order Found") -> https://www.google.com/maps?q=24.476906066431106,54.367972972393915 | I3: الاوردر👇 | J3: =IFERROR(VLOOKUP(A3, AlFayoumi!A:O, 3, FALSE), "No Order Found") -> 20 دجاجه وزن ١٢٠٠ سعر الدجاجه ٢٠ درهم كل دجاجه لحالها | K3: ="🧾 رقم " & C3 & CHAR(10) & "📞 " & D3 & CHAR(10) & "👤 " & E3 & CHAR(10) & "📍 " & F3 & " - " & G3 & CHAR(10) & "🗺️ " & H3 & CHAR(10) & "🛒 الاوردر 👇" & CHAR(10) & J3 & CHAR(10) & "---------------------------" -> 🧾 رقم 2 📞 0523020946 👤 ملك عمرو 📍 امام شارع الدفاع - شارع الفلاح مقابل وير مارت بنايه فريش بالاس الطابق 1408 🗺️ https://www.google.com/maps?q=24.476906066431106,54.367972972393915 🛒 الاوردر 👇 20 دجاجه وزن ١٢٠٠ سعر الدجاجه ٢٠ درهم كل دجاجه لحالها --------------------------- | L3: 2 | M3: ملك عمرو | N3: 3 | O3: Jasmine Behery
A4: =AlFayoumi!A8 -> O1779206737453 | B4: =AlFayoumi!B8 -> C1778243253026 | C4: =IFERROR(VLOOKUP(B4, Routes!B:G, 6, FALSE), "") -> 3 | D4: =VLOOKUP(A4, AlFayoumi!A:O, 5, FALSE) -> 0557827324 | E4: =VLOOKUP(A4, AlFayoumi!A:O, 4, FALSE) -> دعاء صالح | F4: =IFERROR(VLOOKUP(B4, DataBase!A:O, 5, FALSE), "No Order Found") -> شارع النجده | G4: =IFERROR(VLOOKUP(B4, DataBase!A:O, 6, FALSE), "No Order Found") -> شارع للنجده | H4: =IFERROR(VLOOKUP(B4, DataBase!A:O, 7, FALSE), "No Order Found") -> https://www.google.com/maps?q=24.4839877,54.3736343 | I4: الاوردر👇 | J4: =IFERROR(VLOOKUP(A4, AlFayoumi!A:O, 3, FALSE), "No Order Found") -> ١٢ دجاجه بيضا وزن ١٢٠٠ | K4: ="🧾 رقم " & C4 & CHAR(10) & "📞 " & D4 & CHAR(10) & "👤 " & E4 & CHAR(10) & "📍 " & F4 & " - " & G4 & CHAR(10) & "🗺️ " & H4 & CHAR(10) & "🛒 الاوردر 👇" & CHAR(10) & J4 & CHAR(10) & "---------------------------" -> 🧾 رقم 3 📞 0557827324 👤 دعاء صالح 📍 شارع النجده - شارع للنجده 🗺️ https://www.google.com/maps?q=24.4839877,54.3736343 🛒 الاوردر 👇 ١٢ دجاجه بيضا وزن ١٢٠٠ --------------------------- | L4: 3 | M4: دعاء صالح | N4: 7 | O4: مريم رشدى
A5: =AlFayoumi!A7 -> O1779196437405 | B5: =AlFayoumi!B7 -> C1769324778781 | C5: =IFERROR(VLOOKUP(B5, Routes!B:G, 6, FALSE), "") -> 4 | D5: =VLOOKUP(A5, AlFayoumi!A:O, 5, FALSE) -> 0529391713 | E5: =VLOOKUP(A5, AlFayoumi!A:O, 4, FALSE) -> Eman Elkoumy | F5: =IFERROR(VLOOKUP(B5, DataBase!A:O, 5, FALSE), "No Order Found") -> منطقة الريم | G5: =IFERROR(VLOOKUP(B5, DataBase!A:O, 6, FALSE), "No Order Found") -> النور تاور ١٦٠٦ | H5: =IFERROR(VLOOKUP(B5, DataBase!A:O, 7, FALSE), "No Order Found") -> https://www.google.com/maps?q=24.4907523,54.4000173 | I5: الاوردر👇 | J5: =IFERROR(VLOOKUP(A5, AlFayoumi!A:O, 3, FALSE), "No Order Found") -> ٤ كيلو بانيه مش متقطع ٤ كيلو اوراك وزن ١٥٠٠ كل كيلو لوحده | K5: ="🧾 رقم " & C5 & CHAR(10) & "📞 " & L5 & D5 & CHAR(10) & "👤 " & E5 & CHAR(10) & "📍 " & F5 & " - " & G5 & CHAR(10) & "🗺️ " & H5 & CHAR(10) & "🛒 الاوردر 👇" & CHAR(10) & J5 & CHAR(10) & "---------------------------" -> 🧾 رقم 4 📞 40529391713 👤 Eman Elkoumy 📍 منطقة الريم - النور تاور ١٦٠٦ 🗺️ https://www.google.com/maps?q=24.4907523,54.4000173 🛒 الاوردر 👇 ٤ كيلو بانيه مش متقطع ٤ كيلو اوراك وزن ١٥٠٠ كل كيلو لوحده --------------------------- | L5: 4 | M5: Eman Elkoumy | N5: 11 | O5: ريهام احمد
A6: =AlFayoumi!A12 -> O1779289844939 | B6: =AlFayoumi!B12 -> C1776633916549 | C6: =IFERROR(VLOOKUP(B6, Routes!B:G, 6, FALSE), "") -> 5 | D6: =VLOOKUP(A6, AlFayoumi!A:O, 5, FALSE) -> 0585284234 | E6: =VLOOKUP(A6, AlFayoumi!A:O, 4, FALSE) -> Aya | F6: =IFERROR(VLOOKUP(B6, DataBase!A:O, 5, FALSE), "No Order Found") -> المقطع | G6: =IFERROR(VLOOKUP(B6, DataBase!A:O, 6, FALSE), "No Order Found") -> بين الجسرين شارع ام عشر بالقرب من توكيل bmw | H6: =IFERROR(VLOOKUP(B6, DataBase!A:O, 7, FALSE), "No Order Found") -> https://www.google.com/maps?q=24.413685,54.495136 | I6: الاوردر👇 | J6: =IFERROR(VLOOKUP(A6, AlFayoumi!A:O, 3, FALSE), "No Order Found") -> ٢ كيلو صدور سليمه مش متقطعه ٣ فرخات من ١٧٠٠الي ١٨٠٠ | K6: ="🧾 رقم " & C6 & CHAR(10) & "📞 " & D6 & CHAR(10) & "👤 " & E6 & CHAR(10) & "📍 " & F6 & " - " & G6 & CHAR(10) & "🗺️ " & H6 & CHAR(10) & "🛒 الاوردر 👇" & CHAR(10) & J6 & CHAR(10) & "---------------------------" -> 🧾 رقم 5 📞 0585284234 👤 Aya 📍 المقطع - بين الجسرين شارع ام عشر بالقرب من توكيل bmw 🗺️ https://www.google.com/maps?q=24.413685,54.495136 🛒 الاوردر 👇 ٢ كيلو صدور سليمه مش متقطعه ٣ فرخات من ١٧٠٠الي ١٨٠٠ --------------------------- | L6: 5 | M6: Aya | N6: 12 | O6: Zahra
A7: =AlFayoumi!A6 -> O1779192763177 | B7: =AlFayoumi!B6 -> C1778325015999 | C7: =IFERROR(VLOOKUP(B7, Routes!B:G, 6, FALSE), "") -> 6 | D7: =VLOOKUP(A7, AlFayoumi!A:O, 5, FALSE) -> 0528204091 | E7: =VLOOKUP(A7, AlFayoumi!A:O, 4, FALSE) -> Esraa Elwakel | F7: =IFERROR(VLOOKUP(B7, DataBase!A:O, 5, FALSE), "No Order Found") -> ربدان | G7: =IFERROR(VLOOKUP(B7, DataBase!A:O, 6, FALSE), "No Order Found") -> شارع المثابرة بنايه 29 الطابق الثالث نفس بناية مغسلة رويال روز | H7: =IFERROR(VLOOKUP(B7, DataBase!A:O, 7, FALSE), "No Order Found") -> https://www.google.com/maps?q=24.405996821373577,54.517312166606 | I7: الاوردر👇 | J7: =IFERROR(VLOOKUP(A7, AlFayoumi!A:O, 3, FALSE), "No Order Found") -> عدد 5 دجاج ابيضّ وزن 1200 كيلو بانيه كل نص لوحده كيلو صدور بدون عظم كل نصف لوحده | K7: ="🧾 رقم " & C7 & CHAR(10) & "📞 " & D7 & CHAR(10) & "👤 " & E7 & CHAR(10) & "📍 " & F7 & " - " & G7 & CHAR(10) & "🗺️ " & H7 & CHAR(10) & "🛒 الاوردر 👇" & CHAR(10) & J7 & CHAR(10) & "---------------------------" -> 🧾 رقم 6 📞 0528204091 👤 Esraa Elwakel 📍 ربدان - شارع المثابرة بنايه 29 الطابق الثالث نفس بناية مغسلة رويال روز 🗺️ https://www.google.com/maps?q=24.405996821373577,54.517312166606 🛒 الاوردر 👇 عدد 5 دجاج ابيضّ وزن 1200 كيلو بانيه كل نص لوحده كيلو صدور بدون عظم كل نصف لوحده --------------------------- | L7: 6 | M7: Esraa Elwakel | N7: 13 | O7: رانا يسري حسن
A8: =AlFayoumi!A9 -> O1779219097726 | B8: =AlFayoumi!B9 -> C1776515849146 | C8: =IFERROR(VLOOKUP(B8, Routes!B:G, 6, FALSE), "") -> 7 | D8: =VLOOKUP(A8, AlFayoumi!A:O, 5, FALSE) -> 0502358249 | E8: =VLOOKUP(A8, AlFayoumi!A:O, 4, FALSE) -> هاجر محمد | F8: =IFERROR(VLOOKUP(B8, DataBase!A:O, 5, FALSE), "No Order Found") -> ربدان | G8: =IFERROR(VLOOKUP(B8, DataBase!A:O, 6, FALSE), "No Order Found") -> ربدان /شارع اللزيمة /فيلا 40/الدور الثاني شقة 29 | H8: =IFERROR(VLOOKUP(B8, DataBase!A:O, 7, FALSE), "No Order Found") -> https://www.google.com/maps?q=24.4018107,54.519146 | I8: الاوردر👇 | J8: =IFERROR(VLOOKUP(A8, AlFayoumi!A:O, 3, FALSE), "No Order Found") -> ٥ فراخ أبيض وزن 1700_1800 نص كيلو رجل | K8: ="🧾 رقم " & C8 & CHAR(10) & "📞 " & D8 & CHAR(10) & "👤 " & E8 & CHAR(10) & "📍 " & F8 & " - " & G8 & CHAR(10) & "🗺️ " & H8 & CHAR(10) & "🛒 الاوردر 👇" & CHAR(10) & J8 & CHAR(10) & "---------------------------" -> 🧾 رقم 7 📞 0502358249 👤 هاجر محمد 📍 ربدان - ربدان /شارع اللزيمة /فيلا 40/الدور الثاني شقة 29 🗺️ https://www.google.com/maps?q=24.4018107,54.519146 🛒 الاوردر 👇 ٥ فراخ أبيض وزن 1700_1800 نص كيلو رجل --------------------------- | L8: 7 | M8: هاجر محمد | N8: 14 | O8: ملك عمرو
A9: =AlFayoumi!A11 -> O1779285905718 | B9: =AlFayoumi!B11 -> C1768655293606 | C9: =IFERROR(VLOOKUP(B9, Routes!B:G, 6, FALSE), "") -> 8 | D9: =VLOOKUP(A9, AlFayoumi!A:O, 5, FALSE) -> 0555060297 | E9: =VLOOKUP(A9, AlFayoumi!A:O, 4, FALSE) -> Naglaa Eslam | F9: =IFERROR(VLOOKUP(B9, DataBase!A:O, 5, FALSE), "No Order Found") -> خليفه أ | G9: =IFERROR(VLOOKUP(B9, DataBase!A:O, 6, FALSE), "No Order Found") -> ٩١ شارع الكهرمان خليفه خلف الفرسان مول | H9: =IFERROR(VLOOKUP(B9, DataBase!A:O, 7, FALSE), "No Order Found") -> https://www.google.com/maps?q=24.396056135766734,54.5660779698686 | I9: الاوردر👇 | J9: =IFERROR(VLOOKUP(A9, AlFayoumi!A:O, 3, FALSE), "No Order Found") -> 3 فراخات 1200 جرام | K9: ="🧾 رقم " & C9 & CHAR(10) & "📞 " & D9 & CHAR(10) & "👤 " & E9 & CHAR(10) & "📍 " & F9 & " - " & G9 & CHAR(10) & "🗺️ " & H9 & CHAR(10) & "🛒 الاوردر 👇" & CHAR(10) & J9 & CHAR(10) & "---------------------------" -> 🧾 رقم 8 📞 0555060297 👤 Naglaa Eslam 📍 خليفه أ - ٩١ شارع الكهرمان خليفه خلف الفرسان مول 🗺️ https://www.google.com/maps?q=24.396056135766734,54.5660779698686 🛒 الاوردر 👇 3 فراخات 1200 جرام --------------------------- | L9: 8 | M9: Naglaa Eslam | N9: 15 | O9: Mona
A10: =AlFayoumi!A10 -> O1779249920181 | B10: =AlFayoumi!B10 -> C1770412918700 | C10: =IFERROR(VLOOKUP(B10, Routes!B:G, 6, FALSE), "") -> 9 | D10: =VLOOKUP(A10, AlFayoumi!A:O, 5, FALSE) -> 0564507569 | E10: =VLOOKUP(A10, AlFayoumi!A:O, 4, FALSE) -> Heba Motawea | F10: =IFERROR(VLOOKUP(B10, DataBase!A:O, 5, FALSE), "No Order Found") -> شخبوط | G10: =IFERROR(VLOOKUP(B10, DataBase!A:O, 6, FALSE), "No Order Found") -> شخبوط أبوظبي | H10: =IFERROR(VLOOKUP(B10, DataBase!A:O, 7, FALSE), "No Order Found") -> https://www.google.com/maps?q=24.3795837,54.6433836 | I10: الاوردر👇 | J10: =IFERROR(VLOOKUP(A10, AlFayoumi!A:O, 3, FALSE), "No Order Found") -> ٥ دجاج أبيض من ١٥٠٠-١٦٠٠ | K10: ="🧾 رقم " & C10 & CHAR(10) & "📞 " & D10 & CHAR(10) & "👤 " & E10 & CHAR(10) & "📍 " & F10 & " - " & G10 & CHAR(10) & "🗺️ " & H10 & CHAR(10) & "🛒 الاوردر 👇" & CHAR(10) & J10 & CHAR(10) & "---------------------------" -> 🧾 رقم 9 📞 0564507569 👤 Heba Motawea 📍 شخبوط - شخبوط أبوظبي 🗺️ https://www.google.com/maps?q=24.3795837,54.6433836 🛒 الاوردر 👇 ٥ دجاج أبيض من ١٥٠٠-١٦٠٠ --------------------------- | L10: 9 | M10: Heba Motawea | N10: 16 | O10: Alamir
A11: =AlFayoumi!A4 -> O1779192174812 | B11: =AlFayoumi!B4 -> C1778181837755 | C11: =IFERROR(VLOOKUP(B11, Routes!B:G, 6, FALSE), "") -> 10 | D11: =VLOOKUP(A11, AlFayoumi!A:O, 5, FALSE) -> 0508168275 | E11: =VLOOKUP(A11, AlFayoumi!A:O, 4, FALSE) -> هاجر السيد | F11: =IFERROR(VLOOKUP(B11, DataBase!A:O, 5, FALSE), "No Order Found") -> بني ياس | G11: =IFERROR(VLOOKUP(B11, DataBase!A:O, 6, FALSE), "No Order Found") -> بني ياس بوابة الشرق مول شرق 2 فيلا ٢٠ | H11: =IFERROR(VLOOKUP(B11, DataBase!A:O, 7, FALSE), "No Order Found") -> https://www.google.com/maps?q=24.32160286901728,54.62401405136186 | I11: الاوردر👇 | J11: =IFERROR(VLOOKUP(A11, AlFayoumi!A:O, 3, FALSE), "No Order Found") -> 12دجاجة وزن 1200سعر 20درهم | K11: ="🧾 رقم " & C11 & CHAR(10) & "📞 " & D11 & CHAR(10) & "👤 " & E11 & CHAR(10) & "📍 " & F11 & " - " & G11 & CHAR(10) & "🗺️ " & H11 & CHAR(10) & "🛒 الاوردر 👇" & CHAR(10) & J11 & CHAR(10) & "---------------------------" -> 🧾 رقم 10 📞 0508168275 👤 هاجر السيد 📍 بني ياس - بني ياس بوابة الشرق مول شرق 2 فيلا ٢٠ 🗺️ https://www.google.com/maps?q=24.32160286901728,54.62401405136186 🛒 الاوردر 👇 12دجاجة وزن 1200سعر 20درهم --------------------------- | L11: 10 | M11: هاجر السيد | N11: 17 | O11: Enas
A12: =AlFayoumi!A3 -> O1779191777788 | B12: =AlFayoumi!B3 -> C1779191613438 | C12: =IFERROR(VLOOKUP(B12, Routes!B:G, 6, FALSE), "") -> 11 | D12: =VLOOKUP(A12, AlFayoumi!A:O, 5, FALSE) -> 0569233207 | E12: =VLOOKUP(A12, AlFayoumi!A:O, 4, FALSE) -> ساره ذكى | F12: =IFERROR(VLOOKUP(B12, DataBase!A:O, 5, FALSE), "No Order Found") -> ابو ظبى | G12: =IFERROR(VLOOKUP(B12, DataBase!A:O, 6, FALSE), "No Order Found") -> مدينه الرياض فيلا ٢٦ملحق رقم ٣ | H12: =IFERROR(VLOOKUP(B12, DataBase!A:O, 7, FALSE), "No Order Found") -> https://www.google.com/maps?q=24.333568155473717,54.71084769152754 | I12: الاوردر👇 | J12: =IFERROR(VLOOKUP(A12, AlFayoumi!A:O, 3, FALSE), "No Order Found") -> 6فرخات بيضه وزن. ١٢٠٠ | K12: ="🧾 رقم " & C12 & CHAR(10) & "📞 " & D12 & CHAR(10) & "👤 " & E12 & CHAR(10) & "📍 " & F12 & " - " & G12 & CHAR(10) & "🗺️ " & H12 & CHAR(10) & "🛒 الاوردر 👇" & CHAR(10) & J12 & CHAR(10) & "---------------------------" -> 🧾 رقم 11 📞 0569233207 👤 ساره ذكى 📍 ابو ظبى - مدينه الرياض فيلا ٢٦ملحق رقم ٣ 🗺️ https://www.google.com/maps?q=24.333568155473717,54.71084769152754 🛒 الاوردر 👇 6فرخات بيضه وزن. ١٢٠٠ --------------------------- | L12: 11 | M12: ساره ذكى | N12: 19 | O12: ايه احمد
